Traceback (most recent call last):
  File "c:\users\tirab\appdata\local\programs\python\python39\lib\site-packages\jupyter_cache\executors\utils.py", line 58, in single_nb_execution
    executenb(
  File "c:\users\tirab\appdata\local\programs\python\python39\lib\site-packages\nbclient\client.py", line 1305, in execute
    return NotebookClient(nb=nb, resources=resources, km=km, **kwargs).execute()
  File "c:\users\tirab\appdata\local\programs\python\python39\lib\site-packages\jupyter_core\utils\__init__.py", line 166, in wrapped
    return loop.run_until_complete(inner)
  File "c:\users\tirab\appdata\local\programs\python\python39\lib\asyncio\base_events.py", line 642, in run_until_complete
    return future.result()
  File "c:\users\tirab\appdata\local\programs\python\python39\lib\site-packages\nbclient\client.py", line 705, in async_execute
    await self.async_execute_cell(
  File "c:\users\tirab\appdata\local\programs\python\python39\lib\site-packages\nbclient\client.py", line 1058, in async_execute_cell
    await self._check_raise_for_error(cell, cell_index, exec_reply)
  File "c:\users\tirab\appdata\local\programs\python\python39\lib\site-packages\nbclient\client.py", line 914, in _check_raise_for_error
    raise CellExecutionError.from_cell_and_msg(cell, exec_reply_content)
nbclient.exceptions.CellExecutionError: An error occurred while executing the following cell:
------------------
cadena = 'ab'
cadena[0] = 'x'
------------------


[1;31m---------------------------------------------------------------------------[0m
[1;31mTypeError[0m                                 Traceback (most recent call last)
Input [1;32mIn [8][0m, in [0;36m<module>[1;34m[0m
[0;32m      1[0m cadena [38;5;241m=[39m [38;5;124m'[39m[38;5;124mab[39m[38;5;124m'[39m
[1;32m----> 2[0m cadena[[38;5;241m0[39m] [38;5;241m=[39m [38;5;124m'[39m[38;5;124mx[39m[38;5;124m'[39m

[1;31mTypeError[0m: 'str' object does not support item assignment

